Workbook

Sheet Costos corrientes
D1: C | E1: D | F1: E | G1: F | H1: I
C2: Year | D2: Total overnight cost ($/kW) | E2: Variable O&M ($/MWh) | F2: Fixed O&M ($/kW-y) | G2: Heat rate (Btu/kWh) | H2: Lead time (years)
A3: A | B3: Conventional hydropower | C3: 2018 | D3: =IFERROR(INDEX('2018'!$B$2:$P$30,MATCH('Costos corrientes'!$A3,'2018'!$A$2:$A$30,0),MATCH('Costos corrientes'!D$1,'2018'!$B$1:$P$1,0)),NA()) -> 2898 | E3: =IFERROR(INDEX('2018'!$B$2:$P$30,MATCH('Costos corrientes'!$A3,'2018'!$A$2:$A$30,0),MATCH('Costos corrientes'!E$1,'2018'!$B$1:$P$1,0)),NA()) -> 1.33 | F3: =IFERROR(INDEX('2018'!$B$2:$P$30,MATCH('Costos corrientes'!$A3,'2018'!$A$2:$A$30,0),MATCH('Costos corrientes'!F$1,'2018'!$B$1:$P$1,0)),NA()) -> 40.05 | H3: =IFERROR(INDEX('2018'!$B$2:$P$30,MATCH('Costos corrientes'!$A3,'2018'!$A$2:$A$30,0),MATCH('Costos corrientes'!H$1,'2018'!$B$1:$P$1,0)),NA()) -> 4
A4: A | B4: Conventional hydropower | C4: 2019 | D4: =IFERROR(INDEX('2019'!$B$2:$P$30,MATCH('Costos corrientes'!$A4,'2019'!$A$2:$A$30,0),MATCH('Costos corrientes'!D$1,'2019'!$B$1:$P$1,0)),NA()) -> 2948 | E4: =IFERROR(INDEX('2019'!$B$2:$P$30,MATCH('Costos corrientes'!$A4,'2019'!$A$2:$A$30,0),MATCH('Costos corrientes'!E$1,'2019'!$B$1:$P$1,0)),NA()) -> 1.36 | F4: =IFERROR(INDEX('2019'!$B$2:$P$30,MATCH('Costos corrientes'!$A4,'2019'!$A$2:$A$30,0),MATCH('Costos corrientes'!F$1,'2019'!$B$1:$P$1,0)),NA()) -> 40.85 | H4: =IFERROR(INDEX('2019'!$B$2:$P$30,MATCH('Costos corrientes'!$A4,'2019'!$A$2:$A$30,0),MATCH('Costos corrientes'!H$1,'2019'!$B$1:$P$1,0)),NA()) -> 4
A5: A | B5: Conventional hydropower | C5: 2020 | D5: =IFERROR(INDEX('2020'!$B$2:$P$30,MATCH('Costos corrientes'!$A4,'2020'!$A$2:$A$30,0),MATCH('Costos corrientes'!D$1,'2020'!$B$1:$P$1,0)),NA()) -> 2752 | E5: =IFERROR(INDEX('2020'!$B$2:$P$30,MATCH('Costos corrientes'!$A4,'2020'!$A$2:$A$30,0),MATCH('Costos corrientes'!E$1,'2020'!$B$1:$P$1,0)),NA()) -> 1.39 | F5: =IFERROR(INDEX('2020'!$B$2:$P$30,MATCH('Costos corrientes'!$A4,'2020'!$A$2:$A$30,0),MATCH('Costos corrientes'!F$1,'2020'!$B$1:$P$1,0)),NA()) -> 41.63 | H5: =IFERROR(INDEX('2020'!$B$2:$P$30,MATCH('Costos corrientes'!$A4,'2020'!$A$2:$A$30,0),MATCH('Costos corrientes'!H$1,'2020'!$B$1:$P$1,0)),NA()) -> 4
A6: A | B6: Conventional hydropower | C6: 2021 | D6: =IFERROR(INDEX('2021'!$B$2:$P$30,MATCH('Costos corrientes'!$A4,'2021'!$A$2:$A$30,0),MATCH('Costos corrientes'!D$1,'2021'!$B$1:$P$1,0)),NA()) -> 2769 | E6: =IFERROR(INDEX('2021'!$B$2:$P$30,MATCH('Costos corrientes'!$A4,'2021'!$A$2:$A$30,0),MATCH('Costos corrientes'!E$1,'2021'!$B$1:$P$1,0)),NA()) -> 1.4 | F6: =IFERROR(INDEX('2021'!$B$2:$P$30,MATCH('Costos corrientes'!$A4,'2021'!$A$2:$A$30,0),MATCH('Costos corrientes'!F$1,'2021'!$B$1:$P$1,0)),NA()) -> 42.01 | H6: =IFERROR(INDEX('2021'!$B$2:$P$30,MATCH('Costos corrientes'!$A4,'2021'!$A$2:$A$30,0),MATCH('Costos corrientes'!H$1,'2021'!$B$1:$P$1,0)),NA()) -> 4
A7: A | B7: Conventional hydropower | C7: 2022 | D7: =IFERROR(INDEX('2022'!$B$2:$P$30,MATCH('Costos corrientes'!$A4,'2022'!$A$2:$A$30,0),MATCH('Costos corrientes'!D$1,'2022'!$B$1:$P$1,0)),NA()) -> 3083 | E7: =IFERROR(INDEX('2022'!$B$2:$P$30,MATCH('Costos corrientes'!$A4,'2022'!$A$2:$A$30,0),MATCH('Costos corrientes'!E$1,'2022'!$B$1:$P$1,0)),NA()) -> 1.46 | F7: =IFERROR(INDEX('2022'!$B$2:$P$30,MATCH('Costos corrientes'!$A4,'2022'!$A$2:$A$30,0),MATCH('Costos corrientes'!F$1,'2022'!$B$1:$P$1,0)),NA()) -> 43.78 | H7: =IFERROR(INDEX('2022'!$B$2:$P$30,MATCH('Costos corrientes'!$A4,'2022'!$A$2:$A$30,0),MATCH('Costos corrientes'!H$1,'2022'!$B$1:$P$1,0)),NA()) -> 4
A8: A | B8: Conventional hydropower | C8: 2023 | D8: =IFERROR(INDEX('2023'!$B$2:$P$30,MATCH('Costos corrientes'!$A5,'2023'!$A$2:$A$30,0),MATCH('Costos corrientes'!D$1,'2023'!$B$1:$P$1,0)),NA()) -> 3421 | E8: =IFERROR(INDEX('2023'!$B$2:$P$30,MATCH('Costos corrientes'!$A5,'2023'!$A$2:$A$30,0),MATCH('Costos corrientes'!E$1,'2023'!$B$1:$P$1,0)),NA()) -> 1.57 | F8: =IFERROR(INDEX('2023'!$B$2:$P$30,MATCH('Costos corrientes'!$A5,'2023'!$A$2:$A$30,0),MATCH('Costos corrientes'!F$1,'2023'!$B$1:$P$1,0)),NA()) -> 47.06 | H8: =IFERROR(INDEX('2023'!$B$2:$P$30,MATCH('Costos corrientes'!$A5,'2023'!$A$2:$A$30,0),MATCH('Costos corrientes'!H$1,'2023'!$B$1:$P$1,0)),NA()) -> 4
A9: B | B9: Wind | C9: 2018 | D9: =IFERROR(INDEX('2018'!$B$2:$P$30,MATCH('Costos corrientes'!$A9,'2018'!$A$2:$A$30,0),MATCH('Costos corrientes'!D$1,'2018'!$B$1:$P$1,0)),NA()) -> 1657 | E9: =IFERROR(INDEX('2018'!$B$2:$P$30,MATCH('Costos corrientes'!$A9,'2018'!$A$2:$A$30,0),MATCH('Costos corrientes'!E$1,'2018'!$B$1:$P$1,0)),NA()) -> 0 | F9: =IFERROR(INDEX('2018'!$B$2:$P$30,MATCH('Costos corrientes'!$A9,'2018'!$A$2:$A$30,0),MATCH('Costos corrientes'!F$1,'2018'!$B$1:$P$1,0)),NA()) -> 47.47 | H9: =IFERROR(INDEX('2018'!$B$2:$P$30,MATCH('Costos corrientes'!$A9,'2018'!$A$2:$A$30,0),MATCH('Costos corrientes'!H$1,'2018'!$B$1:$P$1,0)),NA()) -> 3
A10: B | B10: Wind | C10: 2019 | D10: =IFERROR(INDEX('2019'!$B$2:$P$30,MATCH('Costos corrientes'!$A10,'2019'!$A$2:$A$30,0),MATCH('Costos corrientes'!D$1,'2019'!$B$1:$P$1,0)),NA()) -> 1624 | E10: =IFERROR(INDEX('2019'!$B$2:$P$30,MATCH('Costos corrientes'!$A10,'2019'!$A$2:$A$30,0),MATCH('Costos corrientes'!E$1,'2019'!$B$1:$P$1,0)),NA()) -> 0 | F10: =IFERROR(INDEX('2019'!$B$2:$P$30,MATCH('Costos corrientes'!$A10,'2019'!$A$2:$A$30,0),MATCH('Costos corrientes'!F$1,'2019'!$B$1:$P$1,0)),NA()) -> 48.42 | H10: =IFERROR(INDEX('2019'!$B$2:$P$30,MATCH('Costos corrientes'!$A10,'2019'!$A$2:$A$30,0),MATCH('Costos corrientes'!H$1,'2019'!$B$1:$P$1,0)),NA()) -> 3
A11: B | B11: Wind | C11: 2020 | D11: =IFERROR(INDEX('2020'!$B$2:$P$30,MATCH('Costos corrientes'!$A10,'2020'!$A$2:$A$30,0),MATCH('Costos corrientes'!D$1,'2020'!$B$1:$P$1,0)),NA()) -> 1319 | E11: =IFERROR(INDEX('2020'!$B$2:$P$30,MATCH('Costos corrientes'!$A10,'2020'!$A$2:$A$30,0),MATCH('Costos corrientes'!E$1,'2020'!$B$1:$P$1,0)),NA()) -> 0 | F11: =IFERROR(INDEX('2020'!$B$2:$P$30,MATCH('Costos corrientes'!$A10,'2020'!$A$2:$A$30,0),MATCH('Costos corrientes'!F$1,'2020'!$B$1:$P$1,0)),NA()) -> 26.22 | H11: =IFERROR(INDEX('2020'!$B$2:$P$30,MATCH('Costos corrientes'!$A10,'2020'!$A$2:$A$30,0),MATCH('Costos corrientes'!H$1,'2020'!$B$1:$P$1,0)),NA()) -> 3
A12: B | B12: Wind | C12: 2021 | D12: =IFERROR(INDEX('2021'!$B$2:$P$30,MATCH('Costos corrientes'!$A10,'2021'!$A$2:$A$30,0),MATCH('Costos corrientes'!D$1,'2021'!$B$1:$P$1,0)),NA()) -> 1846 | E12: =IFERROR(INDEX('2021'!$B$2:$P$30,MATCH('Costos corrientes'!$A10,'2021'!$A$2:$A$30,0),MATCH('Costos corrientes'!E$1,'2021'!$B$1:$P$1,0)),NA()) -> 0 | F12: =IFERROR(INDEX('2021'!$B$2:$P$30,MATCH('Costos corrientes'!$A10,'2021'!$A$2:$A$30,0),MATCH('Costos corrientes'!F$1,'2021'!$B$1:$P$1,0)),NA()) -> 26.47 | H12: =IFERROR(INDEX('2021'!$B$2:$P$30,MATCH('Costos corrientes'!$A10,'2021'!$A$2:$A$30,0),MATCH('Costos corrientes'!H$1,'2021'!$B$1:$P$1,0)),NA()) -> 3
A13: B | B13: Wind | C13: 2022 | D13: =IFERROR(INDEX('2022'!$B$2:$P$30,MATCH('Costos corrientes'!$A10,'2022'!$A$2:$A$30,0),MATCH('Costos corrientes'!D$1,'2022'!$B$1:$P$1,0)),NA()) -> 1718 | E13: =IFERROR(INDEX('2022'!$B$2:$P$30,MATCH('Costos corrientes'!$A10,'2022'!$A$2:$A$30,0),MATCH('Costos corrientes'!E$1,'2022'!$B$1:$P$1,0)),NA()) -> 0 | F13: =IFERROR(INDEX('2022'!$B$2:$P$30,MATCH('Costos corrientes'!$A10,'2022'!$A$2:$A$30,0),MATCH('Costos corrientes'!F$1,'2022'!$B$1:$P$1,0)),NA()) -> 27.57 | H13: =IFERROR(INDEX('2022'!$B$2:$P$30,MATCH('Costos corrientes'!$A10,'2022'!$A$2:$A$30,0),MATCH('Costos corrientes'!H$1,'2022'!$B$1:$P$1,0)),NA()) -> 3
A14: B | B14: Wind | C14: 2023 | D14: =IFERROR(INDEX('2023'!$B$2:$P$30,MATCH('Costos corrientes'!$A11,'2023'!$A$2:$A$30,0),MATCH('Costos corrientes'!D$1,'2023'!$B$1:$P$1,0)),NA()) -> 2098 | E14: =IFERROR(INDEX('2023'!$B$2:$P$30,MATCH('Costos corrientes'!$A11,'2023'!$A$2:$A$30,0),MATCH('Costos corrientes'!E$1,'2023'!$B$1:$P$1,0)),NA()) -> 0 | F14: =IFERROR(INDEX('2023'!$B$2:$P$30,MATCH('Costos corrientes'!$A11,'2023'!$A$2:$A$30,0),MATCH('Costos corrientes'!F$1,'2023'!$B$1:$P$1,0)),NA()) -> 29.64 | H14: =IFERROR(INDEX('2023'!$B$2:$P$30,MATCH('Costos corrientes'!$A11,'2023'!$A$2:$A$30,0),MATCH('Costos corrientes'!H$1,'2023'!$B$1:$P$1,0)),NA()) -> 3
A15: C | B15: Wind offshore | C15: 2018 | D15: =IFERROR(INDEX('2018'!$B$2:$P$30,MATCH('Costos corrientes'!$A15,'2018'!$A$2:$A$30,0),MATCH('Costos corrientes'!D$1,'2018'!$B$1:$P$1,0)),NA()) -> 6454 | E15: =IFERROR(INDEX('2018'!$B$2:$P$30,MATCH('Costos corrientes'!$A15,'2018'!$A$2:$A$30,0),MATCH('Costos corrientes'!E$1,'2018'!$B$1:$P$1,0)),NA()) -> 0 | F15: =IFERROR(INDEX('2018'!$B$2:$P$30,MATCH('Costos corrientes'!$A15,'2018'!$A$2:$A$30,0),MATCH('Costos corrientes'!F$1,'2018'!$B$1:$P$1,0)),NA()) -> 78.56 | H15: =IFERROR(INDEX('2018'!$B$2:$P$30,MATCH('Costos corrientes'!$A15,'2018'!$A$2:$A$30,0),MATCH('Costos corrientes'!H$1,'2018'!$B$1:$P$1,0)),NA()) -> 4
A16: C | B16: Wind offshore | C16: 2019 | D16: =IFERROR(INDEX('2019'!$B$2:$P$30,MATCH('Costos corrientes'!$A16,'2019'!$A$2:$A$30,0),MATCH('Costos corrientes'!D$1,'2019'!$B$1:$P$1,0)),NA()) -> 6542 | E16: =IFERROR(INDEX('2019'!$B$2:$P$30,MATCH('Costos corrientes'!$A16,'2019'!$A$2:$A$30,0),MATCH('Costos corrientes'!E$1,'2019'!$B$1:$P$1,0)),NA()) -> 0 | F16: =IFERROR(INDEX('2019'!$B$2:$P$30,MATCH('Costos corrientes'!$A16,'2019'!$A$2:$A$30,0),MATCH('Costos corrientes'!F$1,'2019'!$B$1:$P$1,0)),NA()) -> 80.14 | H16: =IFERROR(INDEX('2019'!$B$2:$P$30,MATCH('Costos corrientes'!$A16,'2019'!$A$2:$A$30,0),MATCH('Costos corrientes'!H$1,'2019'!$B$1:$P$1,0)),NA()) -> 4
A17: C | B17: Wind offshore | C17: 2020 | D17: =IFERROR(INDEX('2020'!$B$2:$P$30,MATCH('Costos corrientes'!$A16,'2020'!$A$2:$A$30,0),MATCH('Costos corrientes'!D$1,'2020'!$B$1:$P$1,0)),NA()) -> 5446 | E17: =IFERROR(INDEX('2020'!$B$2:$P$30,MATCH('Costos corrientes'!$A16,'2020'!$A$2:$A$30,0),MATCH('Costos corrientes'!E$1,'2020'!$B$1:$P$1,0)),NA()) -> 0 | F17: =IFERROR(INDEX('2020'!$B$2:$P$30,MATCH('Costos corrientes'!$A16,'2020'!$A$2:$A$30,0),MATCH('Costos corrientes'!F$1,'2020'!$B$1:$P$1,0)),NA()) -> 109.54 | H17: =IFERROR(INDEX('2020'!$B$2:$P$30,MATCH('Costos corrientes'!$A16,'2020'!$A$2:$A$30,0),MATCH('Costos corrientes'!H$1,'2020'!$B$1:$P$1,0)),NA()) -> 4
A18: C | B18: Wind offshore | C18: 2021 | D18: =IFERROR(INDEX('2021'!$B$2:$P$30,MATCH('Costos corrientes'!$A16,'2021'!$A$2:$A$30,0),MATCH('Costos corrientes'!D$1,'2021'!$B$1:$P$1,0)),NA()) -> 5453 | E18: =IFERROR(INDEX('2021'!$B$2:$P$30,MATCH('Costos corrientes'!$A16,'2021'!$A$2:$A$30,0),MATCH('Costos corrientes'!E$1,'2021'!$B$1:$P$1,0)),NA()) -> 0 | F18: =IFERROR(INDEX('2021'!$B$2:$P$30,MATCH('Costos corrientes'!$A16,'2021'!$A$2:$A$30,0),MATCH('Costos corrientes'!F$1,'2021'!$B$1:$P$1,0)),NA()) -> 110.56 | H18: =IFERROR(INDEX('2021'!$B$2:$P$30,MATCH('Costos corrientes'!$A16,'2021'!$A$2:$A$30,0),MATCH('Costos corrientes'!H$1,'2021'!$B$1:$P$1,0)),NA()) -> 4
A19: C | B19: Wind offshore | C19: 2022 | D19: =IFERROR(INDEX('2022'!$B$2:$P$30,MATCH('Costos corrientes'!$A16,'2022'!$A$2:$A$30,0),MATCH('Costos corrientes'!D$1,'2022'!$B$1:$P$1,0)),NA()) -> 6041 | E19: =IFERROR(INDEX('2022'!$B$2:$P$30,MATCH('Costos corrientes'!$A16,'2022'!$A$2:$A$30,0),MATCH('Costos corrientes'!E$1,'2022'!$B$1:$P$1,0)),NA()) -> 0 | F19: =IFERROR(INDEX('2022'!$B$2:$P$30,MATCH('Costos corrientes'!$A16,'2022'!$A$2:$A$30,0),MATCH('Costos corrientes'!F$1,'2022'!$B$1:$P$1,0)),NA()) -> 115.16 | H19: =IFERROR(INDEX('2022'!$B$2:$P$30,MATCH('Costos corrientes'!$A16,'2022'!$A$2:$A$30,0),MATCH('Costos corrientes'!H$1,'2022'!$B$1:$P$1,0)),NA()) -> 4
A20: C | B20: Wind offshore | C20: 2023 | D20: =IFERROR(INDEX('2023'!$B$2:$P$30,MATCH('Costos corrientes'!$A17,'2023'!$A$2:$A$30,0),MATCH('Costos corrientes'!D$1,'2023'!$B$1:$P$1,0)),NA()) -> 6672 | E20: =IFERROR(INDEX('2023'!$B$2:$P$30,MATCH('Costos corrientes'!$A17,'2023'!$A$2:$A$30,0),MATCH('Costos corrientes'!E$1,'2023'!$B$1:$P$1,0)),NA()) -> 0 | F20: =IFERROR(INDEX('2023'!$B$2:$P$30,MATCH('Costos corrientes'!$A17,'2023'!$A$2:$A$30,0),MATCH('Costos corrientes'!F$1,'2023'!$B$1:$P$1,0)),NA()) -> 123.81 | H20: =IFERROR(INDEX('2023'!$B$2:$P$30,MATCH('Costos corrientes'!$A17,'2023'!$A$2:$A$30,0),MATCH('Costos corrientes'!H$1,'2023'!$B$1:$P$1,0)),NA()) -> 4
A21: D | B21: Solar thermal | C21: 2018 | D21: =IFERROR(INDEX('2018'!$B$2:$P$30,MATCH('Costos corrientes'!$A21,'2018'!$A$2:$A$30,0),MATCH('Costos corrientes'!D$1,'2018'!$B$1:$P$1,0)),NA()) -> 4228 | E21: =IFERROR(INDEX('2018'!$B$2:$P$30,MATCH('Costos corrientes'!$A21,'2018'!$A$2:$A$30,0),MATCH('Costos corrientes'!E$1,'2018'!$B$1:$P$1,0)),NA()) -> 0 | F21: =IFERROR(INDEX('2018'!$B$2:$P$30,MATCH('Costos corrientes'!$A21,'2018'!$A$2:$A$30,0),MATCH('Costos corrientes'!F$1,'2018'!$B$1:$P$1,0)),NA()) -> 71.41 | H21: =IFERROR(INDEX('2018'!$B$2:$P$30,MATCH('Costos corrientes'!$A21,'2018'!$A$2:$A$30,0),MATCH('Costos corrientes'!H$1,'2018'!$B$1:$P$1,0)),NA()) -> 3
A22: D | B22: Solar thermal | C22: 2019 | D22: =IFERROR(INDEX('2019'!$B$2:$P$30,MATCH('Costos corrientes'!$A22,'2019'!$A$2:$A$30,0),MATCH('Costos corrientes'!D$1,'2019'!$B$1:$P$1,0)),NA()) -> 4291 | E22: =IFERROR(INDEX('2019'!$B$2:$P$30,MATCH('Costos corrientes'!$A22,'2019'!$A$2:$A$30,0),MATCH('Costos corrientes'!E$1,'2019'!$B$1:$P$1,0)),NA()) -> 0 | F22: =IFERROR(INDEX('2019'!$B$2:$P$30,MATCH('Costos corrientes'!$A22,'2019'!$A$2:$A$30,0),MATCH('Costos corrientes'!F$1,'2019'!$B$1:$P$1,0)),NA()) -> 72.84 | H22: =IFERROR(INDEX('2019'!$B$2:$P$30,MATCH('Costos corrientes'!$A22,'2019'!$A$2:$A$30,0),MATCH('Costos corrientes'!H$1,'2019'!$B$1:$P$1,0)),NA()) -> 3
A23: D | B23: Solar thermal | C23: 2020 | D23: =IFERROR(INDEX('2020'!$B$2:$P$30,MATCH('Costos corrientes'!$A22,'2020'!$A$2:$A$30,0),MATCH('Costos corrientes'!D$1,'2020'!$B$1:$P$1,0)),NA()) -> 7191 | E23: =IFERROR(INDEX('2020'!$B$2:$P$30,MATCH('Costos corrientes'!$A22,'2020'!$A$2:$A$30,0),MATCH('Costos corrientes'!E$1,'2020'!$B$1:$P$1,0)),NA()) -> 0 | F23: =IFERROR(INDEX('2020'!$B$2:$P$30,MATCH('Costos corrientes'!$A22,'2020'!$A$2:$A$30,0),MATCH('Costos corrientes'!F$1,'2020'!$B$1:$P$1,0)),NA()) -> 85.03 | H23: =IFERROR(INDEX('2020'!$B$2:$P$30,MATCH('Costos corrientes'!$A22,'2020'!$A$2:$A$30,0),MATCH('Costos corrientes'!H$1,'2020'!$B$1:$P$1,0)),NA()) -> 3
A24: D | B24: Solar thermal | C24: 2021 | D24: =IFERROR(INDEX('2021'!$B$2:$P$30,MATCH('Costos corrientes'!$A22,'2021'!$A$2:$A$30,0),MATCH('Costos corrientes'!D$1,'2021'!$B$1:$P$1,0)),NA()) -> 7116 | E24: =IFERROR(INDEX('2021'!$B$2:$P$30,MATCH('Costos corrientes'!$A22,'2021'!$A$2:$A$30,0),MATCH('Costos corrientes'!E$1,'2021'!$B$1:$P$1,0)),NA()) -> 0 | F24: =IFERROR(INDEX('2021'!$B$2:$P$30,MATCH('Costos corrientes'!$A22,'2021'!$A$2:$A$30,0),MATCH('Costos corrientes'!F$1,'2021'!$B$1:$P$1,0)),NA()) -> 85.82 | H24: =IFERROR(INDEX('2021'!$B$2:$P$30,MATCH('Costos corrientes'!$A22,'2021'!$A$2:$A$30,0),MATCH('Costos corrientes'!H$1,'2021'!$B$1:$P$1,0)),NA()) -> 3
A25: D | B25: Solar thermal | C25: 2022 | D25: =IFERROR(INDEX('2022'!$B$2:$P$30,MATCH('Costos corrientes'!$A22,'2022'!$A$2:$A$30,0),MATCH('Costos corrientes'!D$1,'2022'!$B$1:$P$1,0)),NA()) -> 7895 | E25: =IFERROR(INDEX('2022'!$B$2:$P$30,MATCH('Costos corrientes'!$A22,'2022'!$A$2:$A$30,0),MATCH('Costos corrientes'!E$1,'2022'!$B$1:$P$1,0)),NA()) -> 0 | F25: =IFERROR(INDEX('2022'!$B$2:$P$30,MATCH('Costos corrientes'!$A22,'2022'!$A$2:$A$30,0),MATCH('Costos corrientes'!F$1,'2022'!$B$1:$P$1,0)),NA()) -> 89.39 | H25: =IFERROR(INDEX('2022'!$B$2:$P$30,MATCH('Costos corrientes'!$A22,'2022'!$A$2:$A$30,0),MATCH('Costos corrientes'!H$1,'2022'!$B$1:$P$1,0)),NA()) -> 3
A26: D | B26: Solar thermal | C26: 2023 | D26: =IFERROR(INDEX('2023'!$B$2:$P$30,MATCH('Costos corrientes'!$A23,'2023'!$A$2:$A$30,0),MATCH('Costos corrientes'!D$1,'2023'!$B$1:$P$1,0)),NA()) -> 8732 | E26: =IFERROR(INDEX('2023'!$B$2:$P$30,MATCH('Costos corrientes'!$A23,'2023'!$A$2:$A$30,0),MATCH('Costos corrientes'!E$1,'2023'!$B$1:$P$1,0)),NA()) -> 0 | F26: =IFERROR(INDEX('2023'!$B$2:$P$30,MATCH('Costos corrientes'!$A23,'2023'!$A$2:$A$30,0),MATCH('Costos corrientes'!F$1,'2023'!$B$1:$P$1,0)),NA()) -> 96.1 | H26: =IFERROR(INDEX('2023'!$B$2:$P$30,MATCH('Costos corrientes'!$A23,'2023'!$A$2:$A$30,0),MATCH('Costos corrientes'!H$1,'2023'!$B$1:$P$1,0)),NA()) -> 3
A27: E | B27: Solar PV - tracking | C27: 2018 | D27: =IFERROR(INDEX('2018'!$B$2:$P$30,MATCH('Costos corrientes'!$A27,'2018'!$A$2:$A$30,0),MATCH('Costos corrientes'!D$1,'2018'!$B$1:$P$1,0)),NA()) -> 2105 | E27: =IFERROR(INDEX('2018'!$B$2:$P$30,MATCH('Costos corrientes'!$A27,'2018'!$A$2:$A$30,0),MATCH('Costos corrientes'!E$1,'2018'!$B$1:$P$1,0)),NA()) -> 0 | F27: =IFERROR(INDEX('2018'!$B$2:$P$30,MATCH('Costos corrientes'!$A27,'2018'!$A$2:$A$30,0),MATCH('Costos corrientes'!F$1,'2018'!$B$1:$P$1,0)),NA()) -> 22.02 | H27: =IFERROR(INDEX('2018'!$B$2:$P$30,MATCH('Costos corrientes'!$A27,'2018'!$A$2:$A$30,0),MATCH('Costos corrientes'!H$1,'2018'!$B$1:$P$1,0)),NA()) -> 2
A28: E | B28: Solar PV - tracking | C28: 2019 | D28: =IFERROR(INDEX('2019'!$B$2:$P$30,MATCH('Costos corrientes'!$A28,'2019'!$A$2:$A$30,0),MATCH('Costos corrientes'!D$1,'2019'!$B$1:$P$1,0)),NA()) -> 1969 | E28: =IFERROR(INDEX('2019'!$B$2:$P$30,MATCH('Costos corrientes'!$A28,'2019'!$A$2:$A$30,0),MATCH('Costos corrientes'!E$1,'2019'!$B$1:$P$1,0)),NA()) -> 0 | F28: =IFERROR(INDEX('2019'!$B$2:$P$30,MATCH('Costos corrientes'!$A28,'2019'!$A$2:$A$30,0),MATCH('Costos corrientes'!F$1,'2019'!$B$1:$P$1,0)),NA()) -> 22.46 | H28: =IFERROR(INDEX('2019'!$B$2:$P$30,MATCH('Costos corrientes'!$A28,'2019'!$A$2:$A$30,0),MATCH('Costos corrientes'!H$1,'2019'!$B$1:$P$1,0)),NA()) -> 2
A29: E | B29: Solar PV - tracking | C29: 2020 | D29: =IFERROR(INDEX('2020'!$B$2:$P$30,MATCH('Costos corrientes'!$A28,'2020'!$A$2:$A$30,0),MATCH('Costos corrientes'!D$1,'2020'!$B$1:$P$1,0)),NA()) -> 1331 | E29: =IFERROR(INDEX('2020'!$B$2:$P$30,MATCH('Costos corrientes'!$A28,'2020'!$A$2:$A$30,0),MATCH('Costos corrientes'!E$1,'2020'!$B$1:$P$1,0)),NA()) -> 0 | F29: =IFERROR(INDEX('2020'!$B$2:$P$30,MATCH('Costos corrientes'!$A28,'2020'!$A$2:$A$30,0),MATCH('Costos corrientes'!F$1,'2020'!$B$1:$P$1,0)),NA()) -> 15.19 | H29: =IFERROR(INDEX('2020'!$B$2:$P$30,MATCH('Costos corrientes'!$A28,'2020'!$A$2:$A$30,0),MATCH('Costos corrientes'!H$1,'2020'!$B$1:$P$1,0)),NA()) -> 2
A30: E | B30: Solar PV - tracking | C30: 2021 | D30: =IFERROR(INDEX('2021'!$B$2:$P$30,MATCH('Costos corrientes'!$A28,'2021'!$A$2:$A$30,0),MATCH('Costos corrientes'!D$1,'2021'!$B$1:$P$1,0)),NA()) -> 1248 | E30: =IFERROR(INDEX('2021'!$B$2:$P$30,MATCH('Costos corrientes'!$A28,'2021'!$A$2:$A$30,0),MATCH('Costos corrientes'!E$1,'2021'!$B$1:$P$1,0)),NA()) -> 0 | F30: =IFERROR(INDEX('2021'!$B$2:$P$30,MATCH('Costos corrientes'!$A28,'2021'!$A$2:$A$30,0),MATCH('Costos corrientes'!F$1,'2021'!$B$1:$P$1,0)),NA()) -> 15.33 | H30: =IFERROR(INDEX('2021'!$B$2:$P$30,MATCH('Costos corrientes'!$A28,'2021'!$A$2:$A$30,0),MATCH('Costos corrientes'!H$1,'2021'!$B$1:$P$1,0)),NA()) -> 2
A31: E | B31: Solar PV - tracking | C31: 2022 | D31: =IFERROR(INDEX('2022'!$B$2:$P$30,MATCH('Costos corrientes'!$A28,'2022'!$A$2:$A$30,0),MATCH('Costos corrientes'!D$1,'2022'!$B$1:$P$1,0)),NA()) -> 1327 | E31: =IFERROR(INDEX('2022'!$B$2:$P$30,MATCH('Costos corrientes'!$A28,'2022'!$A$2:$A$30,0),MATCH('Costos corrientes'!E$1,'2022'!$B$1:$P$1,0)),NA()) -> 0 | F31: =IFERROR(INDEX('2022'!$B$2:$P$30,MATCH('Costos corrientes'!$A28,'2022'!$A$2:$A$30,0),MATCH('Costos corrientes'!F$1,'2022'!$B$1:$P$1,0)),NA()) -> 15.97 | H31: =IFERROR(INDEX('2022'!$B$2:$P$30,MATCH('Costos corrientes'!$A28,'2022'!$A$2:$A$30,0),MATCH('Costos corrientes'!H$1,'2022'!$B$1:$P$1,0)),NA()) -> 2
A32: E | B32: Solar PV - tracking | C32: 2023 | D32: =IFERROR(INDEX('2023'!$B$2:$P$30,MATCH('Costos corrientes'!$A29,'2023'!$A$2:$A$30,0),MATCH('Costos corrientes'!D$1,'2023'!$B$1:$P$1,0)),NA()) -> 1448 | E32: =IFERROR(INDEX('2023'!$B$2:$P$30,MATCH('Costos corrientes'!$A29,'2023'!$A$2:$A$30,0),MATCH('Costos corrientes'!E$1,'2023'!$B$1:$P$1,0)),NA()) -> 0 | F32: =IFERROR(INDEX('2023'!$B$2:$P$30,MATCH('Costos corrientes'!$A29,'2023'!$A$2:$A$30,0),MATCH('Costos corrientes'!F$1,'2023'!$B$1:$P$1,0)),NA()) -> 17.16 | H32: =IFERROR(INDEX('2023'!$B$2:$P$30,MATCH('Costos corrientes'!$A29,'2023'!$A$2:$A$30,0),MATCH('Costos corrientes'!H$1,'2023'!$B$1:$P$1,0)),NA()) -> 2
A33: F | B33: Solar PV - fixed tilt | C33: 2018 | D33: =IFERROR(INDEX('2018'!$B$2:$P$30,MATCH('Costos corrientes'!$A33,'2018'!$A$2:$A$30,0),MATCH('Costos corrientes'!D$1,'2018'!$B$1:$P$1,0)),NA()) -> 1851 | E33: =IFERROR(INDEX('2018'!$B$2:$P$30,MATCH('Costos corrientes'!$A33,'2018'!$A$2:$A$30,0),MATCH('Costos corrientes'!E$1,'2018'!$B$1:$P$1,0)),NA()) -> 0 | F33: =IFERROR(INDEX('2018'!$B$2:$P$30,MATCH('Costos corrientes'!$A33,'2018'!$A$2:$A$30,0),MATCH('Costos corrientes'!F$1,'2018'!$B$1:$P$1,0)),NA()) -> 22.02 | H33: =IFERROR(INDEX('2018'!$B$2:$P$30,MATCH('Costos corrientes'!$A33,'2018'!$A$2:$A$30,0),MATCH('Costos corrientes'!H$1,'2018'!$B$1:$P$1,0)),NA()) -> 2
A34: F | B34: Solar PV - fixed tilt | C34: 2019 | D34: =IFERROR(INDEX('2019'!$B$2:$P$30,MATCH('Costos corrientes'!$A34,'2019'!$A$2:$A$30,0),MATCH('Costos corrientes'!D$1,'2019'!$B$1:$P$1,0)),NA()) -> 1783 | E34: =IFERROR(INDEX('2019'!$B$2:$P$30,MATCH('Costos corrientes'!$A34,'2019'!$A$2:$A$30,0),MATCH('Costos corrientes'!E$1,'2019'!$B$1:$P$1,0)),NA()) -> 0 | F34: =IFERROR(INDEX('2019'!$B$2:$P$30,MATCH('Costos corrientes'!$A34,'2019'!$A$2:$A$30,0),MATCH('Costos corrientes'!F$1,'2019'!$B$1:$P$1,0)),NA()) -> 22.46 | H34: =IFERROR(INDEX('2019'!$B$2:$P$30,MATCH('Costos corrientes'!$A34,'2019'!$A$2:$A$30,0),MATCH('Costos corrientes'!H$1,'2019'!$B$1:$P$1,0)),NA()) -> 2
A35: F | B35: Solar PV - fixed tilt | C35: 2020
A36: F | B36: Solar PV - fixed tilt | C36: 2021
A37: F | B37: Solar PV - fixed tilt | C37: 2022
A38: F | B38: Solar PV - fixed tilt | C38: 2023
A39: G | B39: Solar PV with storage | C39: 2018
A40: G | B40: Solar PV with storage | C40: 2019
...

Sheet Costos costantes 2020
B1: 0.064 | C1: 2020 | D1: C | E1: D | F1: E | G1: F | H1: I
C2: Year | D2: Total overnight cost ($/kW) | E2: Variable O&M ($/MWh) | F2: Fixed O&M ($/kW-y) | G2: Heat rate (Btu/kWh) | H2: Lead time (years)
A3: A | B3: Conventional hydropower | C3: 2018 | D3: =IF(SUMIFS('Costos corrientes'!D$3:D$169,'Costos corrientes'!$A$3:$A$169,'Costos costantes 2020'!$A3,'Costos corrientes'!$B$3:$B$169,'Costos costantes 2020'!$B3,'Costos corrientes'!$C$3:$C$169,'Costos costantes 2020'!$C3)>0,SUMIFS('Costos corrientes'!D$3:D$169,'Costos corrientes'!$A$3:$A$169,'Costos costantes 2020'!$A3,'Costos corrientes'!$B$3:$B$169,'Costos costantes 2020'!$B3,'Costos corrientes'!$C$3:$C$169,'Costos costantes 2020'!$C3)/((1+$B$1)^($C3-$C$1)),NA()) -> 3280.8142 | E3: =IF(SUMIFS('Costos corrientes'!E$3:E$169,'Costos corrientes'!$A$3:$A$169,'Costos costantes 2020'!$A3,'Costos corrientes'!$B$3:$B$169,'Costos costantes 2020'!$B3,'Costos corrientes'!$C$3:$C$169,'Costos costantes 2020'!$C3)>0,SUMIFS('Costos corrientes'!E$3:E$169,'Costos corrientes'!$A$3:$A$169,'Costos costantes 2020'!$A3,'Costos corrientes'!$B$3:$B$169,'Costos costantes 2020'!$B3,'Costos corrientes'!$C$3:$C$169,'Costos costantes 2020'!$C3)/((1+$B$1)^($C3-$C$1)),NA()) -> 1.5056877 | F3: =IF(SUMIFS('Costos corrientes'!F$3:F$169,'Costos corrientes'!$A$3:$A$169,'Costos costantes 2020'!$A3,'Costos corrientes'!$B$3:$B$169,'Costos costantes 2020'!$B3,'Costos corrientes'!$C$3:$C$169,'Costos costantes 2020'!$C3)>0,SUMIFS('Costos corrientes'!F$3:F$169,'Costos corrientes'!$A$3:$A$169,'Costos costantes 2020'!$A3,'Costos corrientes'!$B$3:$B$169,'Costos costantes 2020'!$B3,'Costos corrientes'!$C$3:$C$169,'Costos costantes 2020'!$C3)/((1+$B$1)^($C3-$C$1)),NA()) -> 45.340445 | H3: =IFERROR(INDEX('2018'!$B$2:$P$30,MATCH('Costos costantes 2020'!$A3,'2018'!$A$2:$A$30,0),MATCH('Costos costantes 2020'!H$1,'2018'!$B$1:$P$1,0)),NA()) -> 4
A4: A | B4: Conventional hydropower | C4: 2019 | D4: =IF(SUMIFS('Costos corrientes'!D$3:D$169,'Costos corrientes'!$A$3:$A$169,'Costos costantes 2020'!$A4,'Costos corrientes'!$B$3:$B$169,'Costos costantes 2020'!$B4,'Costos corrientes'!$C$3:$C$169,'Costos costantes 2020'!$C4)>0,SUMIFS('Costos corrientes'!D$3:D$169,'Costos corrientes'!$A$3:$A$169,'Costos costantes 2020'!$A4,'Costos corrientes'!$B$3:$B$169,'Costos costantes 2020'!$B4,'Costos corrientes'!$C$3:$C$169,'Costos costantes 2020'!$C4)/((1+$B$1)^($C4-$C$1)),NA()) -> 3136.672 | E4: =IF(SUMIFS('Costos corrientes'!E$3:E$169,'Costos corrientes'!$A$3:$A$169,'Costos costantes 2020'!$A4,'Costos corrientes'!$B$3:$B$169,'Costos costantes 2020'!$B4,'Costos corrientes'!$C$3:$C$169,'Costos costantes 2020'!$C4)>0,SUMIFS('Costos corrientes'!E$3:E$169,'Costos corrientes'!$A$3:$A$169,'Costos costantes 2020'!$A4,'Costos corrientes'!$B$3:$B$169,'Costos costantes 2020'!$B4,'Costos corrientes'!$C$3:$C$169,'Costos costantes 2020'!$C4)/((1+$B$1)^($C4-$C$1)),NA()) -> 1.44704 | F4: =IF(SUMIFS('Costos corrientes'!F$3:F$169,'Costos corrientes'!$A$3:$A$169,'Costos costantes 2020'!$A4,'Costos corrientes'!$B$3:$B$169,'Costos costantes 2020'!$B4,'Costos corrientes'!$C$3:$C$169,'Costos costantes 2020'!$C4)>0,SUMIFS('Costos corrientes'!F$3:F$169,'Costos corrientes'!$A$3:$A$169,'Costos costantes 2020'!$A4,'Costos corrientes'!$B$3:$B$169,'Costos costantes 2020'!$B4,'Costos corrientes'!$C$3:$C$169,'Costos costantes 2020'!$C4)/((1+$B$1)^($C4-$C$1)),NA()) -> 43.4644 | H4: =IFERROR(INDEX('2019'!$B$2:$P$30,MATCH('Costos costantes 2020'!$A4,'2019'!$A$2:$A$30,0),MATCH('Costos costantes 2020'!H$1,'2019'!$B$1:$P$1,0)),NA()) -> 4
A5: A | B5: Conventional hydropower | C5: 2020 | D5: =IF(SUMIFS('Costos corrientes'!D$3:D$169,'Costos corrientes'!$A$3:$A$169,'Costos costantes 2020'!$A5,'Costos corrientes'!$B$3:$B$169,'Costos costantes 2020'!$B5,'Costos corrientes'!$C$3:$C$169,'Costos costantes 2020'!$C5)>0,SUMIFS('Costos corrientes'!D$3:D$169,'Costos corrientes'!$A$3:$A$169,'Costos costantes 2020'!$A5,'Costos corrientes'!$B$3:$B$169,'Costos costantes 2020'!$B5,'Costos corrientes'!$C$3:$C$169,'Costos costantes 2020'!$C5)/((1+$B$1)^($C5-$C$1)),NA()) -> 2752 | E5: =IF(SUMIFS('Costos corrientes'!E$3:E$169,'Costos corrientes'!$A$3:$A$169,'Costos costantes 2020'!$A5,'Costos corrientes'!$B$3:$B$169,'Costos costantes 2020'!$B5,'Costos corrientes'!$C$3:$C$169,'Costos costantes 2020'!$C5)>0,SUMIFS('Costos corrientes'!E$3:E$169,'Costos corrientes'!$A$3:$A$169,'Costos costantes 2020'!$A5,'Costos corrientes'!$B$3:$B$169,'Costos costantes 2020'!$B5,'Costos corrientes'!$C$3:$C$169,'Costos costantes 2020'!$C5)/((1+$B$1)^($C5-$C$1)),NA()) -> 1.39 | F5: =IF(SUMIFS('Costos corrientes'!F$3:F$169,'Costos corrientes'!$A$3:$A$169,'Costos costantes 2020'!$A5,'Costos corrientes'!$B$3:$B$169,'Costos costantes 2020'!$B5,'Costos corrientes'!$C$3:$C$169,'Costos costantes 2020'!$C5)>0,SUMIFS('Costos corrientes'!F$3:F$169,'Costos corrientes'!$A$3:$A$169,'Costos costantes 2020'!$A5,'Costos corrientes'!$B$3:$B$169,'Costos costantes 2020'!$B5,'Costos corrientes'!$C$3:$C$169,'Costos costantes 2020'!$C5)/((1+$B$1)^($C5-$C$1)),NA()) -> 41.63 | H5: =IFERROR(INDEX('2020'!$B$2:$P$30,MATCH('Costos costantes 2020'!$A4,'2020'!$A$2:$A$30,0),MATCH('Costos costantes 2020'!H$1,'2020'!$B$1:$P$1,0)),NA()) -> 4
A6: A | B6: Conventional hydropower | C6: 2021 | D6: =IF(SUMIFS('Costos corrientes'!D$3:D$169,'Costos corrientes'!$A$3:$A$169,'Costos costantes 2020'!$A6,'Costos corrientes'!$B$3:$B$169,'Costos costantes 2020'!$B6,'Costos corrientes'!$C$3:$C$169,'Costos costantes 2020'!$C6)>0,SUMIFS('Costos corrientes'!D$3:D$169,'Costos corrientes'!$A$3:$A$169,'Costos costantes 2020'!$A6,'Costos corrientes'!$B$3:$B$169,'Costos costantes 2020'!$B6,'Costos corrientes'!$C$3:$C$169,'Costos costantes 2020'!$C6)/((1+$B$1)^($C6-$C$1)),NA()) -> 2602.4436 | E6: =IF(SUMIFS('Costos corrientes'!E$3:E$169,'Costos corrientes'!$A$3:$A$169,'Costos costantes 2020'!$A6,'Costos corrientes'!$B$3:$B$169,'Costos costantes 2020'!$B6,'Costos corrientes'!$C$3:$C$169,'Costos costantes 2020'!$C6)>0,SUMIFS('Costos corrientes'!E$3:E$169,'Costos corrientes'!$A$3:$A$169,'Costos costantes 2020'!$A6,'Costos corrientes'!$B$3:$B$169,'Costos costantes 2020'!$B6,'Costos corrientes'!$C$3:$C$169,'Costos costantes 2020'!$C6)/((1+$B$1)^($C6-$C$1)),NA()) -> 1.3157895 | F6: =IF(SUMIFS('Costos corrientes'!F$3:F$169,'Costos corrientes'!$A$3:$A$169,'Costos costantes 2020'!$A6,'Costos corrientes'!$B$3:$B$169,'Costos costantes 2020'!$B6,'Costos corrientes'!$C$3:$C$169,'Costos costantes 2020'!$C6)>0,SUMIFS('Costos corrientes'!F$3:F$169,'Costos corrientes'!$A$3:$A$169,'Costos costantes 2020'!$A6,'Costos corrientes'!$B$3:$B$169,'Costos costantes 2020'!$B6,'Costos corrientes'!$C$3:$C$169,'Costos costantes 2020'!$C6)/((1+$B$1)^($C6-$C$1)),NA()) -> 39.483083 | H6: =IFERROR(INDEX('2021'!$B$2:$P$30,MATCH('Costos costantes 2020'!$A4,'2021'!$A$2:$A$30,0),MATCH('Costos costantes 2020'!H$1,'2021'!$B$1:$P$1,0)),NA()) -> 4
A7: A | B7: Conventional hydropower | C7: 2022 | D7: =IF(SUMIFS('Costos corrientes'!D$3:D$169,'Costos corrientes'!$A$3:$A$169,'Costos costantes 2020'!$A7,'Costos corrientes'!$B$3:$B$169,'Costos costantes 2020'!$B7,'Costos corrientes'!$C$3:$C$169,'Costos costantes 2020'!$C7)>0,SUMIFS('Costos corrientes'!D$3:D$169,'Costos corrientes'!$A$3:$A$169,'Costos costantes 2020'!$A7,'Costos corrientes'!$B$3:$B$169,'Costos costantes 2020'!$B7,'Costos corrientes'!$C$3:$C$169,'Costos costantes 2020'!$C7)/((1+$B$1)^($C7-$C$1)),NA()) -> 2723.2673 | E7: =IF(SUMIFS('Costos corrientes'!E$3:E$169,'Costos corrientes'!$A$3:$A$169,'Costos costantes 2020'!$A7,'Costos corrientes'!$B$3:$B$169,'Costos costantes 2020'!$B7,'Costos corrientes'!$C$3:$C$169,'Costos costantes 2020'!$C7)>0,SUMIFS('Costos corrientes'!E$3:E$169,'Costos corrientes'!$A$3:$A$169,'Costos costantes 2020'!$A7,'Costos corrientes'!$B$3:$B$169,'Costos costantes 2020'!$B7,'Costos corrientes'!$C$3:$C$169,'Costos costantes 2020'!$C7)/((1+$B$1)^($C7-$C$1)),NA()) -> 1.2896433 | F7: =IF(SUMIFS('Costos corrientes'!F$3:F$169,'Costos corrientes'!$A$3:$A$169,'Costos costantes 2020'!$A7,'Costos corrientes'!$B$3:$B$169,'Costos costantes 2020'!$B7,'Costos corrientes'!$C$3:$C$169,'Costos costantes 2020'!$C7)>0,SUMIFS('Costos corrientes'!F$3:F$169,'Costos corrientes'!$A$3:$A$169,'Costos costantes 2020'!$A7,'Costos corrientes'!$B$3:$B$169,'Costos costantes 2020'!$B7,'Costos corrientes'!$C$3:$C$169,'Costos costantes 2020'!$C7)/((1+$B$1)^($C7-$C$1)),NA()) -> 38.671632 | H7: =IFERROR(INDEX('2022'!$B$2:$P$30,MATCH('Costos costantes 2020'!$A4,'2022'!$A$2:$A$30,0),MATCH('Costos costantes 2020'!H$1,'2022'!$B$1:$P$1,0)),NA()) -> 4
A8: A | B8: Conventional hydropower | C8: 2023 | D8: =IF(SUMIFS('Costos corrientes'!D$3:D$169,'Costos corrientes'!$A$3:$A$169,'Costos costantes 2020'!$A8,'Costos corrientes'!$B$3:$B$169,'Costos costantes 2020'!$B8,'Costos corrientes'!$C$3:$C$169,'Costos costantes 2020'!$C8)>0,SUMIFS('Costos corrientes'!D$3:D$169,'Costos corrientes'!$A$3:$A$169,'Costos costantes 2020'!$A8,'Costos corrientes'!$B$3:$B$169,'Costos costantes 2020'!$B8,'Costos corrientes'!$C$3:$C$169,'Costos costantes 2020'!$C8)/((1+$B$1)^($C8-$C$1)),NA()) -> 2840.0644 | E8: =IF(SUMIFS('Costos corrientes'!E$3:E$169,'Costos corrientes'!$A$3:$A$169,'Costos costantes 2020'!$A8,'Costos corrientes'!$B$3:$B$169,'Costos costantes 2020'!$B8,'Costos corrientes'!$C$3:$C$169,'Costos costantes 2020'!$C8)>0,SUMIFS('Costos corrientes'!E$3:E$169,'Costos corrientes'!$A$3:$A$169,'Costos costantes 2020'!$A8,'Costos corrientes'!$B$3:$B$169,'Costos costantes 2020'!$B8,'Costos corrientes'!$C$3:$C$169,'Costos costantes 2020'!$C8)/((1+$B$1)^($C8-$C$1)),NA()) -> 1.3033912 | F8: =IF(SUMIFS('Costos corrientes'!F$3:F$169,'Costos corrientes'!$A$3:$A$169,'Costos costantes 2020'!$A8,'Costos corrientes'!$B$3:$B$169,'Costos costantes 2020'!$B8,'Costos corrientes'!$C$3:$C$169,'Costos costantes 2020'!$C8)>0,SUMIFS('Costos corrientes'!F$3:F$169,'Costos corrientes'!$A$3:$A$169,'Costos costantes 2020'!$A8,'Costos corrientes'!$B$3:$B$169,'Costos costantes 2020'!$B8,'Costos corrientes'!$C$3:$C$169,'Costos costantes 2020'!$C8)/((1+$B$1)^($C8-$C$1)),NA()) -> 39.068527 | H8: =IFERROR(INDEX('2022'!$B$2:$P$30,MATCH('Costos costantes 2020'!$A5,'2022'!$A$2:$A$30,0),MATCH('Costos costantes 2020'!H$1,'2022'!$B$1:$P$1,0)),NA()) -> 4
A9: B | B9: Wind | C9: 2018 | D9: =IF(SUMIFS('Costos corrientes'!D$3:D$169,'Costos corrientes'!$A$3:$A$169,'Costos costantes 2020'!$A9,'Costos corrientes'!$B$3:$B$169,'Costos costantes 2020'!$B9,'Costos corrientes'!$C$3:$C$169,'Costos costantes 2020'!$C9)>0,SUMIFS('Costos corrientes'!D$3:D$169,'Costos corrientes'!$A$3:$A$169,'Costos costantes 2020'!$A9,'Costos corrientes'!$B$3:$B$169,'Costos costantes 2020'!$B9,'Costos corrientes'!$C$3:$C$169,'Costos costantes 2020'!$C9)/((1+$B$1)^($C9-$C$1)),NA()) -> 1875.8831 | E9: =IF(SUMIFS('Costos corrientes'!E$3:E$169,'Costos corrientes'!$A$3:$A$169,'Costos costantes 2020'!$A9,'Costos corrientes'!$B$3:$B$169,'Costos costantes 2020'!$B9,'Costos corrientes'!$C$3:$C$169,'Costos costantes 2020'!$C9)>0,SUMIFS('Costos corrientes'!E$3:E$169,'Costos corrientes'!$A$3:$A$169,'Costos costantes 2020'!$A9,'Costos corrientes'!$B$3:$B$169,'Costos costantes 2020'!$B9,'Costos corrientes'!$C$3:$C$169,'Costos costantes 2020'!$C9)/((1+$B$1)^($C9-$C$1)),NA()) -> #N/A | F9: =IF(SUMIFS('Costos corrientes'!F$3:F$169,'Costos corrientes'!$A$3:$A$169,'Costos costantes 2020'!$A9,'Costos corrientes'!$B$3:$B$169,'Costos costantes 2020'!$B9,'Costos corrientes'!$C$3:$C$169,'Costos costantes 2020'!$C9)>0,SUMIFS('Costos corrientes'!F$3:F$169,'Costos corrientes'!$A$3:$A$169,'Costos costantes 2020'!$A9,'Costos corrientes'!$B$3:$B$169,'Costos costantes 2020'!$B9,'Costos corrientes'!$C$3:$C$169,'Costos costantes 2020'!$C9)/((1+$B$1)^($C9-$C$1)),NA()) -> 53.740597 | H9: =IFERROR(INDEX('2018'!$B$2:$P$30,MATCH('Costos costantes 2020'!$A9,'2018'!$A$2:$A$30,0),MATCH('Costos costantes 2020'!H$1,'2018'!$B$1:$P$1,0)),NA()) -> 3
A10: B | B10: Wind | C10: 2019 | D10: =IF(SUMIFS('Costos corrientes'!D$3:D$169,'Costos corrientes'!$A$3:$A$169,'Costos costantes 2020'!$A10,'Costos corrientes'!$B$3:$B$169,'Costos costantes 2020'!$B10,'Costos corrientes'!$C$3:$C$169,'Costos costantes 2020'!$C10)>0,SUMIFS('Costos corrientes'!D$3:D$169,'Costos corrientes'!$A$3:$A$169,'Costos costantes 2020'!$A10,'Costos corrientes'!$B$3:$B$169,'Costos costantes 2020'!$B10,'Costos corrientes'!$C$3:$C$169,'Costos costantes 2020'!$C10)/((1+$B$1)^($C10-$C$1)),NA()) -> 1727.936 | E10: =IF(SUMIFS('Costos corrientes'!E$3:E$169,'Costos corrientes'!$A$3:$A$169,'Costos costantes 2020'!$A10,'Costos corrientes'!$B$3:$B$169,'Costos costantes 2020'!$B10,'Costos corrientes'!$C$3:$C$169,'Costos costantes 2020'!$C10)>0,SUMIFS('Costos corrientes'!E$3:E$169,'Costos corrientes'!$A$3:$A$169,'Costos costantes 2020'!$A10,'Costos corrientes'!$B$3:$B$169,'Costos costantes 2020'!$B10,'Costos corrientes'!$C$3:$C$169,'Costos costantes 2020'!$C10)/((1+$B$1)^($C10-$C$1)),NA()) -> #N/A | F10: =IF(SUMIFS('Costos corrientes'!F$3:F$169,'Costos corrientes'!$A$3:$A$169,'Costos costantes 2020'!$A10,'Costos corrientes'!$B$3:$B$169,'Costos costantes 2020'!$B10,'Costos corrientes'!$C$3:$C$169,'Costos costantes 2020'!$C10)>0,SUMIFS('Costos corrientes'!F$3:F$169,'Costos corrientes'!$A$3:$A$169,'Costos costantes 2020'!$A10,'Costos corrientes'!$B$3:$B$169,'Costos costantes 2020'!$B10,'Costos corrientes'!$C$3:$C$169,'Costos costantes 2020'!$C10)/((1+$B$1)^($C10-$C$1)),NA()) -> 51.51888 | H10: =IFERROR(INDEX('2019'!$B$2:$P$30,MATCH('Costos costantes 2020'!$A10,'2019'!$A$2:$A$30,0),MATCH('Costos costantes 2020'!H$1,'2019'!$B$1:$P$1,0)),NA()) -> 3
A11: B | B11: Wind | C11: 2020 | D11: =IF(SUMIFS('Costos corrientes'!D$3:D$169,'Costos corrientes'!$A$3:$A$169,'Costos costantes 2020'!$A11,'Costos corrientes'!$B$3:$B$169,'Costos costantes 2020'!$B11,'Costos corrientes'!$C$3:$C$169,'Costos costantes 2020'!$C11)>0,SUMIFS('Costos corrientes'!D$3:D$169,'Costos corrientes'!$A$3:$A$169,'Costos costantes 2020'!$A11,'Costos corrientes'!$B$3:$B$169,'Costos costantes 2020'!$B11,'Costos corrientes'!$C$3:$C$169,'Costos costantes 2020'!$C11)/((1+$B$1)^($C11-$C$1)),NA()) -> 1319 | E11: =IF(SUMIFS('Costos corrientes'!E$3:E$169,'Costos corrientes'!$A$3:$A$169,'Costos costantes 2020'!$A11,'Costos corrientes'!$B$3:$B$169,'Costos costantes 2020'!$B11,'Costos corrientes'!$C$3:$C$169,'Costos costantes 2020'!$C11)>0,SUMIFS('Costos corrientes'!E$3:E$169,'Costos corrientes'!$A$3:$A$169,'Costos costantes 2020'!$A11,'Costos corrientes'!$B$3:$B$169,'Costos costantes 2020'!$B11,'Costos corrientes'!$C$3:$C$169,'Costos costantes 2020'!$C11)/((1+$B$1)^($C11-$C$1)),NA()) -> #N/A | F11: =IF(SUMIFS('Costos corrientes'!F$3:F$169,'Costos corrientes'!$A$3:$A$169,'Costos costantes 2020'!$A11,'Costos corrientes'!$B$3:$B$169,'Costos costantes 2020'!$B11,'Costos corrientes'!$C$3:$C$169,'Costos costantes 2020'!$C11)>0,SUMIFS('Costos corrientes'!F$3:F$169,'Costos corrientes'!$A$3:$A$169,'Costos costantes 2020'!$A11,'Costos corrientes'!$B$3:$B$169,'Costos costantes 2020'!$B11,'Costos corrientes'!$C$3:$C$169,'Costos costantes 2020'!$C11)/((1+$B$1)^($C11-$C$1)),NA()) -> 26.22 | H11: =IFERROR(INDEX('2020'!$B$2:$P$30,MATCH('Costos costantes 2020'!$A10,'2020'!$A$2:$A$30,0),MATCH('Costos costantes 2020'!H$1,'2020'!$B$1:$P$1,0)),NA()) -> 3
A12: B | B12: Wind | C12: 2021 | D12: =IF(SUMIFS('Costos corrientes'!D$3:D$169,'Costos corrientes'!$A$3:$A$169,'Costos costantes 2020'!$A12,'Costos corrientes'!$B$3:$B$169,'Costos costantes 2020'!$B12,'Costos corrientes'!$C$3:$C$169,'Costos costantes 2020'!$C12)>0,SUMIFS('Costos corrientes'!D$3:D$169,'Costos corrientes'!$A$3:$A$169,'Costos costantes 2020'!$A12,'Costos corrientes'!$B$3:$B$169,'Costos costantes 2020'!$B12,'Costos corrientes'!$C$3:$C$169,'Costos costantes 2020'!$C12)/((1+$B$1)^($C12-$C$1)),NA()) -> 1734.9624 | E12: =IF(SUMIFS('Costos corrientes'!E$3:E$169,'Costos corrientes'!$A$3:$A$169,'Costos costantes 2020'!$A12,'Costos corrientes'!$B$3:$B$169,'Costos costantes 2020'!$B12,'Costos corrientes'!$C$3:$C$169,'Costos costantes 2020'!$C12)>0,SUMIFS('Costos corrientes'!E$3:E$169,'Costos corrientes'!$A$3:$A$169,'Costos costantes 2020'!$A12,'Costos corrientes'!$B$3:$B$169,'Costos costantes 2020'!$B12,'Costos corrientes'!$C$3:$C$169,'Costos costantes 2020'!$C12)/((1+$B$1)^($C12-$C$1)),NA()) -> #N/A | F12: =IF(SUMIFS('Costos corrientes'!F$3:F$169,'Costos corrientes'!$A$3:$A$169,'Costos costantes 2020'!$A12,'Costos corrientes'!$B$3:$B$169,'Costos costantes 2020'!$B12,'Costos corrientes'!$C$3:$C$169,'Costos costantes 2020'!$C12)>0,SUMIFS('Costos corrientes'!F$3:F$169,'Costos corrientes'!$A$3:$A$169,'Costos costantes 2020'!$A12,'Costos corrientes'!$B$3:$B$169,'Costos costantes 2020'!$B12,'Costos corrientes'!$C$3:$C$169,'Costos costantes 2020'!$C12)/((1+$B$1)^($C12-$C$1)),NA()) -> 24.87782 | H12: =IFERROR(INDEX('2021'!$B$2:$P$30,MATCH('Costos costantes 2020'!$A10,'2021'!$A$2:$A$30,0),MATCH('Costos costantes 2020'!H$1,'2021'!$B$1:$P$1,0)),NA()) -> 3
A13: B | B13: Wind | C13: 2022 | D13: =IF(SUMIFS('Costos corrientes'!D$3:D$169,'Costos corrientes'!$A$3:$A$169,'Costos costantes 2020'!$A13,'Costos corrientes'!$B$3:$B$169,'Costos costantes 2020'!$B13,'Costos corrientes'!$C$3:$C$169,'Costos costantes 2020'!$C13)>0,SUMIFS('Costos corrientes'!D$3:D$169,'Costos corrientes'!$A$3:$A$169,'Costos costantes 2020'!$A13,'Costos corrientes'!$B$3:$B$169,'Costos costantes 2020'!$B13,'Costos corrientes'!$C$3:$C$169,'Costos costantes 2020'!$C13)/((1+$B$1)^($C13-$C$1)),NA()) -> 1517.5391 | E13: =IF(SUMIFS('Costos corrientes'!E$3:E$169,'Costos corrientes'!$A$3:$A$169,'Costos costantes 2020'!$A13,'Costos corrientes'!$B$3:$B$169,'Costos costantes 2020'!$B13,'Costos corrientes'!$C$3:$C$169,'Costos costantes 2020'!$C13)>0,SUMIFS('Costos corrientes'!E$3:E$169,'Costos corrientes'!$A$3:$A$169,'Costos costantes 2020'!$A13,'Costos corrientes'!$B$3:$B$169,'Costos costantes 2020'!$B13,'Costos corrientes'!$C$3:$C$169,'Costos costantes 2020'!$C13)/((1+$B$1)^($C13-$C$1)),NA()) -> #N/A | F13: =IF(SUMIFS('Costos corrientes'!F$3:F$169,'Costos corrientes'!$A$3:$A$169,'Costos costantes 2020'!$A13,'Costos corrientes'!$B$3:$B$169,'Costos costantes 2020'!$B13,'Costos corrientes'!$C$3:$C$169,'Costos costantes 2020'!$C13)>0,SUMIFS('Costos corrientes'!F$3:F$169,'Costos corrientes'!$A$3:$A$169,'Costos costantes 2020'!$A13,'Costos corrientes'!$B$3:$B$169,'Costos costantes 2020'!$B13,'Costos corrientes'!$C$3:$C$169,'Costos costantes 2020'!$C13)/((1+$B$1)^($C13-$C$1)),NA()) -> 24.353058 | H13: =IFERROR(INDEX('2022'!$B$2:$P$30,MATCH('Costos costantes 2020'!$A10,'2022'!$A$2:$A$30,0),MATCH('Costos costantes 2020'!H$1,'2022'!$B$1:$P$1,0)),NA()) -> 3
A14: B | B14: Wind | C14: 2023 | D14: =IF(SUMIFS('Costos corrientes'!D$3:D$169,'Costos corrientes'!$A$3:$A$169,'Costos costantes 2020'!$A14,'Costos corrientes'!$B$3:$B$169,'Costos costantes 2020'!$B14,'Costos corrientes'!$C$3:$C$169,'Costos costantes 2020'!$C14)>0,SUMIFS('Costos corrientes'!D$3:D$169,'Costos corrientes'!$A$3:$A$169,'Costos costantes 2020'!$A14,'Costos corrientes'!$B$3:$B$169,'Costos costantes 2020'!$B14,'Costos corrientes'!$C$3:$C$169,'Costos costantes 2020'!$C14)/((1+$B$1)^($C14-$C$1)),NA()) -> 1741.7291 | E14: =IF(SUMIFS('Costos corrientes'!E$3:E$169,'Costos corrientes'!$A$3:$A$169,'Costos costantes 2020'!$A14,'Costos corrientes'!$B$3:$B$169,'Costos costantes 2020'!$B14,'Costos corrientes'!$C$3:$C$169,'Costos costantes 2020'!$C14)>0,SUMIFS('Costos corrientes'!E$3:E$169,'Costos corrientes'!$A$3:$A$169,'Costos costantes 2020'!$A14,'Costos corrientes'!$B$3:$B$169,'Costos costantes 2020'!$B14,'Costos corrientes'!$C$3:$C$169,'Costos costantes 2020'!$C14)/((1+$B$1)^($C14-$C$1)),NA()) -> #N/A | F14: =IF(SUMIFS('Costos corrientes'!F$3:F$169,'Costos corrientes'!$A$3:$A$169,'Costos costantes 2020'!$A14,'Costos corrientes'!$B$3:$B$169,'Costos costantes 2020'!$B14,'Costos corrientes'!$C$3:$C$169,'Costos costantes 2020'!$C14)>0,SUMIFS('Costos corrientes'!F$3:F$169,'Costos corrientes'!$A$3:$A$169,'Costos costantes 2020'!$A14,'Costos corrientes'!$B$3:$B$169,'Costos costantes 2020'!$B14,'Costos corrientes'!$C$3:$C$169,'Costos costantes 2020'!$C14)/((1+$B$1)^($C14-$C$1)),NA()) -> 24.606697 | H14: =IFERROR(INDEX('2022'!$B$2:$P$30,MATCH('Costos costantes 2020'!$A11,'2022'!$A$2:$A$30,0),MATCH('Costos costantes 2020'!H$1,'2022'!$B$1:$P$1,0)),NA()) -> 3
A15: C | B15: Wind offshore | C15: 2018 | D15: =IF(SUMIFS('Costos corrientes'!D$3:D$169,'Costos corrientes'!$A$3:$A$169,'Costos costantes 2020'!$A15,'Costos corrientes'!$B$3:$B$169,'Costos costantes 2020'!$B15,'Costos corrientes'!$C$3:$C$169,'Costos costantes 2020'!$C15)>0,SUMIFS('Costos corrientes'!D$3:D$169,'Costos corrientes'!$A$3:$A$169,'Costos costantes 2020'!$A15,'Costos corrientes'!$B$3:$B$169,'Costos costantes 2020'!$B15,'Costos corrientes'!$C$3:$C$169,'Costos costantes 2020'!$C15)/((1+$B$1)^($C15-$C$1)),NA()) -> 7306.5476 | E15: =IF(SUMIFS('Costos corrientes'!E$3:E$169,'Costos corrientes'!$A$3:$A$169,'Costos costantes 2020'!$A15,'Costos corrientes'!$B$3:$B$169,'Costos costantes 2020'!$B15,'Costos corrientes'!$C$3:$C$169,'Costos costantes 2020'!$C15)>0,SUMIFS('Costos corrientes'!E$3:E$169,'Costos corrientes'!$A$3:$A$169,'Costos costantes 2020'!$A15,'Costos corrientes'!$B$3:$B$169,'Costos costantes 2020'!$B15,'Costos corrientes'!$C$3:$C$169,'Costos costantes 2020'!$C15)/((1+$B$1)^($C15-$C$1)),NA()) -> #N/A | F15: =IF(SUMIFS('Costos corrientes'!F$3:F$169,'Costos corrientes'!$A$3:$A$169,'Costos costantes 2020'!$A15,'Costos corrientes'!$B$3:$B$169,'Costos costantes 2020'!$B15,'Costos corrientes'!$C$3:$C$169,'Costos costantes 2020'!$C15)>0,SUMIFS('Costos corrientes'!F$3:F$169,'Costos corrientes'!$A$3:$A$169,'Costos costantes 2020'!$A15,'Costos corrientes'!$B$3:$B$169,'Costos costantes 2020'!$B15,'Costos corrientes'!$C$3:$C$169,'Costos costantes 2020'!$C15)/((1+$B$1)^($C15-$C$1)),NA()) -> 88.937462 | H15: =IFERROR(INDEX('2018'!$B$2:$P$30,MATCH('Costos costantes 2020'!$A15,'2018'!$A$2:$A$30,0),MATCH('Costos costantes 2020'!H$1,'2018'!$B$1:$P$1,0)),NA()) -> 4
A16: C | B16: Wind offshore | C16: 2019 | D16: =IF(SUMIFS('Costos corrientes'!D$3:D$169,'Costos corrientes'!$A$3:$A$169,'Costos costantes 2020'!$A16,'Costos corrientes'!$B$3:$B$169,'Costos costantes 2020'!$B16,'Costos corrientes'!$C$3:$C$169,'Costos costantes 2020'!$C16)>0,SUMIFS('Costos corrientes'!D$3:D$169,'Costos corrientes'!$A$3:$A$169,'Costos costantes 2020'!$A16,'Costos corrientes'!$B$3:$B$169,'Costos costantes 2020'!$B16,'Costos corrientes'!$C$3:$C$169,'Costos costantes 2020'!$C16)/((1+$B$1)^($C16-$C$1)),NA()) -> 6960.688 | E16: =IF(SUMIFS('Costos corrientes'!E$3:E$169,'Costos corrientes'!$A$3:$A$169,'Costos costantes 2020'!$A16,'Costos corrientes'!$B$3:$B$169,'Costos costantes 2020'!$B16,'Costos corrientes'!$C$3:$C$169,'Costos costantes 2020'!$C16)>0,SUMIFS('Costos corrientes'!E$3:E$169,'Costos corrientes'!$A$3:$A$169,'Costos costantes 2020'!$A16,'Costos corrientes'!$B$3:$B$169,'Costos costantes 2020'!$B16,'Costos corrientes'!$C$3:$C$169,'Costos costantes 2020'!$C16)/((1+$B$1)^($C16-$C$1)),NA()) -> #N/A | F16: =IF(SUMIFS('Costos corrientes'!F$3:F$169,'Costos corrientes'!$A$3:$A$169,'Costos costantes 2020'!$A16,'Costos corrientes'!$B$3:$B$169,'Costos costantes 2020'!$B16,'Costos corrientes'!$C$3:$C$169,'Costos costantes 2020'!$C16)>0,SUMIFS('Costos corrientes'!F$3:F$169,'Costos corrientes'!$A$3:$A$169,'Costos costantes 2020'!$A16,'Costos corrientes'!$B$3:$B$169,'Costos costantes 2020'!$B16,'Costos corrientes'!$C$3:$C$169,'Costos costantes 2020'!$C16)/((1+$B$1)^($C16-$C$1)),NA()) -> 85.26896 | H16: =IFERROR(INDEX('2019'!$B$2:$P$30,MATCH('Costos costantes 2020'!$A16,'2019'!$A$2:$A$30,0),MATCH('Costos costantes 2020'!H$1,'2019'!$B$1:$P$1,0)),NA()) -> 4
A17: C | B17: Wind offshore | C17: 2020 | D17: =IF(SUMIFS('Costos corrientes'!D$3:D$169,'Costos corrientes'!$A$3:$A$169,'Costos costantes 2020'!$A17,'Costos corrientes'!$B$3:$B$169,'Costos costantes 2020'!$B17,'Costos corrientes'!$C$3:$C$169,'Costos costantes 2020'!$C17)>0,SUMIFS('Costos corrientes'!D$3:D$169,'Costos corrientes'!$A$3:$A$169,'Costos costantes 2020'!$A17,'Costos corrientes'!$B$3:$B$169,'Costos costantes 2020'!$B17,'Costos corrientes'!$C$3:$C$169,'Costos costantes 2020'!$C17)/((1+$B$1)^($C17-$C$1)),NA()) -> 5446 | E17: =IF(SUMIFS('Costos corrientes'!E$3:E$169,'Costos corrientes'!$A$3:$A$169,'Costos costantes 2020'!$A17,'Costos corrientes'!$B$3:$B$169,'Costos costantes 2020'!$B17,'Costos corrientes'!$C$3:$C$169,'Costos costantes 2020'!$C17)>0,SUMIFS('Costos corrientes'!E$3:E$169,'Costos corrientes'!$A$3:$A$169,'Costos costantes 2020'!$A17,'Costos corrientes'!$B$3:$B$169,'Costos costantes 2020'!$B17,'Costos corrientes'!$C$3:$C$169,'Costos costantes 2020'!$C17)/((1+$B$1)^($C17-$C$1)),NA()) -> #N/A | F17: =IF(SUMIFS('Costos corrientes'!F$3:F$169,'Costos corrientes'!$A$3:$A$169,'Costos costantes 2020'!$A17,'Costos corrientes'!$B$3:$B$169,'Costos costantes 2020'!$B17,'Costos corrientes'!$C$3:$C$169,'Costos costantes 2020'!$C17)>0,SUMIFS('Costos corrientes'!F$3:F$169,'Costos corrientes'!$A$3:$A$169,'Costos costantes 2020'!$A17,'Costos corrientes'!$B$3:$B$169,'Costos costantes 2020'!$B17,'Costos corrientes'!$C$3:$C$169,'Costos costantes 2020'!$C17)/((1+$B$1)^($C17-$C$1)),NA()) -> 109.54 | H17: =IFERROR(INDEX('2020'!$B$2:$P$30,MATCH('Costos costantes 2020'!$A16,'2020'!$A$2:$A$30,0),MATCH('Costos costantes 2020'!H$1,'2020'!$B$1:$P$1,0)),NA()) -> 4
A18: C | B18: Wind offshore | C18: 2021 | D18: =IF(SUMIFS('Costos corrientes'!D$3:D$169,'Costos corrientes'!$A$3:$A$169,'Costos costantes 2020'!$A18,'Costos corrientes'!$B$3:$B$169,'Costos costantes 2020'!$B18,'Costos corrientes'!$C$3:$C$169,'Costos costantes 2020'!$C18)>0,SUMIFS('Costos corrientes'!D$3:D$169,'Costos corrientes'!$A$3:$A$169,'Costos costantes 2020'!$A18,'Costos corrientes'!$B$3:$B$169,'Costos costantes 2020'!$B18,'Costos corrientes'!$C$3:$C$169,'Costos costantes 2020'!$C18)/((1+$B$1)^($C18-$C$1)),NA()) -> 5125 | E18: =IF(SUMIFS('Costos corrientes'!E$3:E$169,'Costos corrientes'!$A$3:$A$169,'Costos costantes 2020'!$A18,'Costos corrientes'!$B$3:$B$169,'Costos costantes 2020'!$B18,'Costos corrientes'!$C$3:$C$169,'Costos costantes 2020'!$C18)>0,SUMIFS('Costos corrientes'!E$3:E$169,'Costos corrientes'!$A$3:$A$169,'Costos costantes 2020'!$A18,'Costos corrientes'!$B$3:$B$169,'Costos costantes 2020'!$B18,'Costos corrientes'!$C$3:$C$169,'Costos costantes 2020'!$C18)/((1+$B$1)^($C18-$C$1)),NA()) -> #N/A | F18: =IF(SUMIFS('Costos corrientes'!F$3:F$169,'Costos corrientes'!$A$3:$A$169,'Costos costantes 2020'!$A18,'Costos corrientes'!$B$3:$B$169,'Costos costantes 2020'!$B18,'Costos corrientes'!$C$3:$C$169,'Costos costantes 2020'!$C18)>0,SUMIFS('Costos corrientes'!F$3:F$169,'Costos corrientes'!$A$3:$A$169,'Costos costantes 2020'!$A18,'Costos corrientes'!$B$3:$B$169,'Costos costantes 2020'!$B18,'Costos corrientes'!$C$3:$C$169,'Costos costantes 2020'!$C18)/((1+$B$1)^($C18-$C$1)),NA()) -> 103.90977 | H18: =IFERROR(INDEX('2021'!$B$2:$P$30,MATCH('Costos costantes 2020'!$A16,'2021'!$A$2:$A$30,0),MATCH('Costos costantes 2020'!H$1,'2021'!$B$1:$P$1,0)),NA()) -> 4
A19: C | B19: Wind offshore | C19: 2022 | D19: =IF(SUMIFS('Costos corrientes'!D$3:D$169,'Costos corrientes'!$A$3:$A$169,'Costos costantes 2020'!$A19,'Costos corrientes'!$B$3:$B$169,'Costos costantes 2020'!$B19,'Costos corrientes'!$C$3:$C$169,'Costos costantes 2020'!$C19)>0,SUMIFS('Costos corrientes'!D$3:D$169,'Costos corrientes'!$A$3:$A$169,'Costos costantes 2020'!$A19,'Costos corrientes'!$B$3:$B$169,'Costos costantes 2020'!$B19,'Costos corrientes'!$C$3:$C$169,'Costos costantes 2020'!$C19)/((1+$B$1)^($C19-$C$1)),NA()) -> 5336.1199 | E19: =IF(SUMIFS('Costos corrientes'!E$3:E$169,'Costos corrientes'!$A$3:$A$169,'Costos costantes 2020'!$A19,'Costos corrientes'!$B$3:$B$169,'Costos costantes 2020'!$B19,'Costos corrientes'!$C$3:$C$169,'Costos costantes 2020'!$C19)>0,SUMIFS('Costos corrientes'!E$3:E$169,'Costos corrientes'!$A$3:$A$169,'Costos costantes 2020'!$A19,'Costos corrientes'!$B$3:$B$169,'Costos costantes 2020'!$B19,'Costos corrientes'!$C$3:$C$169,'Costos costantes 2020'!$C19)/((1+$B$1)^($C19-$C$1)),NA()) -> #N/A | F19: =IF(SUMIFS('Costos corrientes'!F$3:F$169,'Costos corrientes'!$A$3:$A$169,'Costos costantes 2020'!$A19,'Costos corrientes'!$B$3:$B$169,'Costos costantes 2020'!$B19,'Costos corrientes'!$C$3:$C$169,'Costos costantes 2020'!$C19)>0,SUMIFS('Costos corrientes'!F$3:F$169,'Costos corrientes'!$A$3:$A$169,'Costos costantes 2020'!$A19,'Costos corrientes'!$B$3:$B$169,'Costos costantes 2020'!$B19,'Costos corrientes'!$C$3:$C$169,'Costos costantes 2020'!$C19)/((1+$B$1)^($C19-$C$1)),NA()) -> 101.72282 | H19: =IFERROR(INDEX('2022'!$B$2:$P$30,MATCH('Costos costantes 2020'!$A16,'2022'!$A$2:$A$30,0),MATCH('Costos costantes 2020'!H$1,'2022'!$B$1:$P$1,0)),NA()) -> 4
A20: C | B20: Wind offshore | C20: 2023 | D20: =IF(SUMIFS('Costos corrientes'!D$3:D$169,'Costos corrientes'!$A$3:$A$169,'Costos costantes 2020'!$A20,'Costos corrientes'!$B$3:$B$169,'Costos costantes 2020'!$B20,'Costos corrientes'!$C$3:$C$169,'Costos costantes 2020'!$C20)>0,SUMIFS('Costos corrientes'!D$3:D$169,'Costos corrientes'!$A$3:$A$169,'Costos costantes 2020'!$A20,'Costos corrientes'!$B$3:$B$169,'Costos costantes 2020'!$B20,'Costos corrientes'!$C$3:$C$169,'Costos costantes 2020'!$C20)/((1+$B$1)^($C20-$C$1)),NA()) -> 5538.9973 | E20: =IF(SUMIFS('Costos corrientes'!E$3:E$169,'Costos corrientes'!$A$3:$A$169,'Costos costantes 2020'!$A20,'Costos corrientes'!$B$3:$B$169,'Costos costantes 2020'!$B20,'Costos corrientes'!$C$3:$C$169,'Costos costantes 2020'!$C20)>0,SUMIFS('Costos corrientes'!E$3:E$169,'Costos corrientes'!$A$3:$A$169,'Costos costantes 2020'!$A20,'Costos corrientes'!$B$3:$B$169,'Costos costantes 2020'!$B20,'Costos corrientes'!$C$3:$C$169,'Costos costantes 2020'!$C20)/((1+$B$1)^($C20-$C$1)),NA()) -> #N/A | F20: =IF(SUMIFS('Costos corrientes'!F$3:F$169,'Costos corrientes'!$A$3:$A$169,'Costos costantes 2020'!$A20,'Costos corrientes'!$B$3:$B$169,'Costos costantes 2020'!$B20,'Costos corrientes'!$C$3:$C$169,'Costos costantes 2020'!$C20)>0,SUMIFS('Costos corrientes'!F$3:F$169,'Costos corrientes'!$A$3:$A$169,'Costos costantes 2020'!$A20,'Costos corrientes'!$B$3:$B$169,'Costos costantes 2020'!$B20,'Costos corrientes'!$C$3:$C$169,'Costos costantes 2020'!$C20)/((1+$B$1)^($C20-$C$1)),NA()) -> 102.78526 | H20: =IFERROR(INDEX('2022'!$B$2:$P$30,MATCH('Costos costantes 2020'!$A17,'2022'!$A$2:$A$30,0),MATCH('Costos costantes 2020'!H$1,'2022'!$B$1:$P$1,0)),NA()) -> 4
A21: D | B21: Solar thermal | C21: 2018 | D21: =IF(SUMIFS('Costos corrientes'!D$3:D$169,'Costos corrientes'!$A$3:$A$169,'Costos costantes 2020'!$A21,'Costos corrientes'!$B$3:$B$169,'Costos costantes 2020'!$B21,'Costos corrientes'!$C$3:$C$169,'Costos costantes 2020'!$C21)>0,SUMIFS('Costos corrientes'!D$3:D$169,'Costos corrientes'!$A$3:$A$169,'Costos costantes 2020'!$A21,'Costos corrientes'!$B$3:$B$169,'Costos costantes 2020'!$B21,'Costos corrientes'!$C$3:$C$169,'Costos costantes 2020'!$C21)/((1+$B$1)^($C21-$C$1)),NA()) -> 4786.5019 | E21: =IF(SUMIFS('Costos corrientes'!E$3:E$169,'Costos corrientes'!$A$3:$A$169,'Costos costantes 2020'!$A21,'Costos corrientes'!$B$3:$B$169,'Costos costantes 2020'!$B21,'Costos corrientes'!$C$3:$C$169,'Costos costantes 2020'!$C21)>0,SUMIFS('Costos corrientes'!E$3:E$169,'Costos corrientes'!$A$3:$A$169,'Costos costantes 2020'!$A21,'Costos corrientes'!$B$3:$B$169,'Costos costantes 2020'!$B21,'Costos corrientes'!$C$3:$C$169,'Costos costantes 2020'!$C21)/((1+$B$1)^($C21-$C$1)),NA()) -> #N/A | F21: =IF(SUMIFS('Costos corrientes'!F$3:F$169,'Costos corrientes'!$A$3:$A$169,'Costos costantes 2020'!$A21,'Costos corrientes'!$B$3:$B$169,'Costos costantes 2020'!$B21,'Costos corrientes'!$C$3:$C$169,'Costos costantes 2020'!$C21)>0,SUMIFS('Costos corrientes'!F$3:F$169,'Costos corrientes'!$A$3:$A$169,'Costos costantes 2020'!$A21,'Costos corrientes'!$B$3:$B$169,'Costos costantes 2020'!$B21,'Costos corrientes'!$C$3:$C$169,'Costos costantes 2020'!$C21)/((1+$B$1)^($C21-$C$1)),NA()) -> 80.842975 | H21: =IFERROR(INDEX('2018'!$B$2:$P$30,MATCH('Costos costantes 2020'!$A21,'2018'!$A$2:$A$30,0),MATCH('Costos costantes 2020'!H$1,'2018'!$B$1:$P$1,0)),NA()) -> 3
A22: D | B22: Solar thermal | C22: 2019 | D22: =IF(SUMIFS('Costos corrientes'!D$3:D$169,'Costos corrientes'!$A$3:$A$169,'Costos costantes 2020'!$A22,'Costos corrientes'!$B$3:$B$169,'Costos costantes 2020'!$B22,'Costos corrientes'!$C$3:$C$169,'Costos costantes 2020'!$C22)>0,SUMIFS('Costos corrientes'!D$3:D$169,'Costos corrientes'!$A$3:$A$169,'Costos costantes 2020'!$A22,'Costos corrientes'!$B$3:$B$169,'Costos costantes 2020'!$B22,'Costos corrientes'!$C$3:$C$169,'Costos costantes 2020'!$C22)/((1+$B$1)^($C22-$C$1)),NA()) -> 4565.624 | E22: =IF(SUMIFS('Costos corrientes'!E$3:E$169,'Costos corrientes'!$A$3:$A$169,'Costos costantes 2020'!$A22,'Costos corrientes'!$B$3:$B$169,'Costos costantes 2020'!$B22,'Costos corrientes'!$C$3:$C$169,'Costos costantes 2020'!$C22)>0,SUMIFS('Costos corrientes'!E$3:E$169,'Costos corrientes'!$A$3:$A$169,'Costos costantes 2020'!$A22,'Costos corrientes'!$B$3:$B$169,'Costos costantes 2020'!$B22,'Costos corrientes'!$C$3:$C$169,'Costos costantes 2020'!$C22)/((1+$B$1)^($C22-$C$1)),NA()) -> #N/A | F22: =IF(SUMIFS('Costos corrientes'!F$3:F$169,'Costos corrientes'!$A$3:$A$169,'Costos costantes 2020'!$A22,'Costos corrientes'!$B$3:$B$169,'Costos costantes 2020'!$B22,'Costos corrientes'!$C$3:$C$169,'Costos costantes 2020'!$C22)>0,SUMIFS('Costos corrientes'!F$3:F$169,'Costos corrientes'!$A$3:$A$169,'Costos costantes 2020'!$A22,'Costos corrientes'!$B$3:$B$169,'Costos costantes 2020'!$B22,'Costos corrientes'!$C$3:$C$169,'Costos costantes 2020'!$C22)/((1+$B$1)^($C22-$C$1)),NA()) -> 77.50176 | H22: =IFERROR(INDEX('2019'!$B$2:$P$30,MATCH('Costos costantes 2020'!$A22,'2019'!$A$2:$A$30,0),MATCH('Costos costantes 2020'!H$1,'2019'!$B$1:$P$1,0)),NA()) -> 3
A23: D | B23: Solar thermal | C23: 2020 | D23: =IF(SUMIFS('Costos corrientes'!D$3:D$169,'Costos corrientes'!$A$3:$A$169,'Costos costantes 2020'!$A23,'Costos corrientes'!$B$3:$B$169,'Costos costantes 2020'!$B23,'Costos corrientes'!$C$3:$C$169,'Costos costantes 2020'!$C23)>0,SUMIFS('Costos corrientes'!D$3:D$169,'Costos corrientes'!$A$3:$A$169,'Costos costantes 2020'!$A23,'Costos corrientes'!$B$3:$B$169,'Costos costantes 2020'!$B23,'Costos corrientes'!$C$3:$C$169,'Costos costantes 2020'!$C23)/((1+$B$1)^($C23-$C$1)),NA()) -> 7191 | E23: =IF(SUMIFS('Costos corrientes'!E$3:E$169,'Costos corrientes'!$A$3:$A$169,'Costos costantes 2020'!$A23,'Costos corrientes'!$B$3:$B$169,'Costos costantes 2020'!$B23,'Costos corrientes'!$C$3:$C$169,'Costos costantes 2020'!$C23)>0,SUMIFS('Costos corrientes'!E$3:E$169,'Costos corrientes'!$A$3:$A$169,'Costos costantes 2020'!$A23,'Costos corrientes'!$B$3:$B$169,'Costos costantes 2020'!$B23,'Costos corrientes'!$C$3:$C$169,'Costos costantes 2020'!$C23)/((1+$B$1)^($C23-$C$1)),NA()) -> #N/A | F23: =IF(SUMIFS('Costos corrientes'!F$3:F$169,'Costos corrientes'!$A$3:$A$169,'Costos costantes 2020'!$A23,'Costos corrientes'!$B$3:$B$169,'Costos costantes 2020'!$B23,'Costos corrientes'!$C$3:$C$169,'Costos costantes 2020'!$C23)>0,SUMIFS('Costos corrientes'!F$3:F$169,'Costos corrientes'!$A$3:$A$169,'Costos costantes 2020'!$A23,'Costos corrientes'!$B$3:$B$169,'Costos costantes 2020'!$B23,'Costos corrientes'!$C$3:$C$169,'Costos costantes 2020'!$C23)/((1+$B$1)^($C23-$C$1)),NA()) -> 85.03 | H23: =IFERROR(INDEX('2020'!$B$2:$P$30,MATCH('Costos costantes 2020'!$A22,'2020'!$A$2:$A$30,0),MATCH('Costos costantes 2020'!H$1,'2020'!$B$1:$P$1,0)),NA()) -> 3
A24: D | B24: Solar thermal | C24: 2021 | D24: =IF(SUMIFS('Costos corrientes'!D$3:D$169,'Costos corrientes'!$A$3:$A$169,'Costos costantes 2020'!$A24,'Costos corrientes'!$B$3:$B$169,'Costos costantes 2020'!$B24,'Costos corrientes'!$C$3:$C$169,'Costos costantes 2020'!$C24)>0,SUMIFS('Costos corrientes'!D$3:D$169,'Costos corrientes'!$A$3:$A$169,'Costos costantes 2020'!$A24,'Costos corrientes'!$B$3:$B$169,'Costos costantes 2020'!$B24,'Costos corrientes'!$C$3:$C$169,'Costos costantes 2020'!$C24)/((1+$B$1)^($C24-$C$1)),NA()) -> 6687.9699 | E24: =IF(SUMIFS('Costos corrientes'!E$3:E$169,'Costos corrientes'!$A$3:$A$169,'Costos costantes 2020'!$A24,'Costos corrientes'!$B$3:$B$169,'Costos costantes 2020'!$B24,'Costos corrientes'!$C$3:$C$169,'Costos costantes 2020'!$C24)>0,SUMIFS('Costos corrientes'!E$3:E$169,'Costos corrientes'!$A$3:$A$169,'Costos costantes 2020'!$A24,'Costos corrientes'!$B$3:$B$169,'Costos costantes 2020'!$B24,'Costos corrientes'!$C$3:$C$169,'Costos costantes 2020'!$C24)/((1+$B$1)^($C24-$C$1)),NA()) -> #N/A | F24: =IF(SUMIFS('Costos corrientes'!F$3:F$169,'Costos corrientes'!$A$3:$A$169,'Costos costantes 2020'!$A24,'Costos corrientes'!$B$3:$B$169,'Costos costantes 2020'!$B24,'Costos corrientes'!$C$3:$C$169,'Costos costantes 2020'!$C24)>0,SUMIFS('Costos corrientes'!F$3:F$169,'Costos corrientes'!$A$3:$A$169,'Costos costantes 2020'!$A24,'Costos corrientes'!$B$3:$B$169,'Costos costantes 2020'!$B24,'Costos corrientes'!$C$3:$C$169,'Costos costantes 2020'!$C24)/((1+$B$1)^($C24-$C$1)),NA()) -> 80.657895 | H24: =IFERROR(INDEX('2021'!$B$2:$P$30,MATCH('Costos costantes 2020'!$A22,'2021'!$A$2:$A$30,0),MATCH('Costos costantes 2020'!H$1,'2021'!$B$1:$P$1,0)),NA()) -> 3
